<?xml version="1.0" ?>
 
<robot name="arm" xmlns:xacro="http://www.ros.org/wiki/xacro">

            <!-- Materials -->
<material name="green">
<color rgba="0 0.8 0 1"/>
</material>

<material name="red">
<color rgba="1 0 0 0.8"/>
</material>

<material name="blue">
<color rgba="0 0 1 0.8"/>
</material>

            <!-- Use world link for fixing the robot-->
<link name="world"/>
    <inertial>
        <mass value = "0.00001" />
        <origin rpy ="0 0 0" xyz ="0 0 0" />
        <inertia ixx = "0.0" ixy = "0.0" ixz = "0.0" iyy = "0.0" iyz = "0.0" izz = "0.0" />
    </inertial>

  <joint name="fixed" type="fixed">
    <parent link="world"/>
    <child link="arm_base_bottom"/>
  </joint>

            <!-- Base Bottom Link -->
<link name="arm_base_bottom">

    <inertial>
        <mass value = "0.00001" />
        <origin rpy ="0 0 0" xyz ="0 0 0" />
        <inertia ixx = "0.00" ixy = "0.00" ixz = "0.00" iyy = "0.00" iyz = "0.00" izz = "0.00" />
    </inertial>

    <visual>
        <origin rpy="0 0 0" xyz="0 0 0"/>
            <geometry>
                <box size="0.05 0.05 0.01"/>
            </geometry>
            <material name="green"/>
    </visual>

</link>

        <!-- Base Bottom to Base Joint -->

<joint name="base_joint" type="revolute">
    <parent link="arm_base_bottom"/>
        <child link="arm_base"/>
        <origin xyz="0 0 0.005" rpy="0 0 0"/>
        <limit lower="-3.14159" upper="3.14159" effort="5.4917" velocity="0.5"/>
    <axis xyz="0 0 1"/>
</joint>

<transmission name = "trans_bottom_base">
    <type>transmission_interface/SimpleTransmission</type>
    <joint name="base_joint">
        <hardwareInterface>hardware_interface/EffortJointInterface</hardwareInterface>
    </joint>
    <actuator name="motor_base_joint">
        <hardwareInterface>hardware_interface/EffortJointInterface</hardwareInterface>
        <mechanicalReduction>1</mechanicalReduction>
    </actuator>
</transmission>

            <!-- Arm Base Link -->

<link name="arm_base">
    <inertial>
        <mass value = "0.1" />
        <origin rpy ="0 0 0" xyz ="0 0 0.035" />
        <inertia ixx = "0.01" ixy = "0.01" ixz = "0.01" iyy = "0.01" iyz = "0.01" izz = "0.01" />
    </inertial>


    <visual>
        <origin rpy="0 0 0" xyz="0 0 0.035"/>
            <geometry>
                <box size="0.05 0.05 0.07"/>
            </geometry>
            <material name="green"/>
    </visual>
</link>

        <!-- Base to Lower Joint-->

<joint name="base_lower_joint" type="revolute">
    <parent link="arm_base"/>
        <child link="arm_lower"/>
        <origin xyz="0 0 0.07" rpy="0 0 0"/>
        <limit lower="-1.57" upper="1.57" effort="5.4917" velocity="0.5"/>
    <axis xyz="1 0 0"/>
</joint>

<transmission name = "trans_base_lower">
    <type>transmission_interface/SimpleTransmission</type>
    <joint name="base_lower_joint">
        <hardwareInterface>hardware_interface/EffortJointInterface</hardwareInterface>
    </joint>
    <actuator name="motor_base_lower_joint">
        <hardwareInterface>hardware_interface/EffortJointInterface</hardwareInterface>
        <mechanicalReduction>1</mechanicalReduction>
    </actuator>
</transmission>

            <!-- Arm Lower Link -->
            
<link name="arm_lower">
    <inertial>
        <mass value = "0.1" />
        <origin rpy ="0 0 0" xyz ="0 0 0.216" />
        <inertia ixx = "0.01" ixy = "0.01" ixz = "0.01" iyy = "0.01" iyz = "0.01" izz = "0.01" />
    </inertial>

    <collision>
        <origin rpy="0 0 0" xyz="0 0 0.216"/>
            <geometry>
                <box size="0.0254 0.0254  0.432"/>
            </geometry>
    </collision>

    <visual>
        <origin rpy="0 0 0" xyz="0 0 0.216"/>
            <geometry>
                <box size="0.0254 0.0254  0.432"/>
            </geometry>
            <material name="blue"/>
    </visual>
</link>

          <!-- Lower to Upper Joint -->

<joint name="lower_upper_joint" type="revolute">
    <parent link="arm_lower"/>
        <child link="arm_upper"/>
        <origin xyz="0 0 0.432" rpy="0 0 0"/>
        <limit lower="-3.14159" upper="3.14159" effort="5.4917" velocity="0.5"/>
    <axis xyz="1 0 0"/>
</joint>

<transmission name = "trans_lower_upper">
    <type>transmission_interface/SimpleTransmission</type>
    <joint name="lower_upper_joint">
        <hardwareInterface>hardware_interface/EffortJointInterface</hardwareInterface>
    </joint>
    <actuator name="motor_lower_upper_joint">
        <hardwareInterface>hardware_interface/EffortJointInterface</hardwareInterface>
        <mechanicalReduction>1</mechanicalReduction>
    </actuator>
</transmission>

            <!-- Arm Upper Link -->

<link name="arm_upper">

    <inertial>
        <mass value = "0.1" />
        <origin rpy ="0 0 0" xyz ="0.0252 0 0.27" />
        <inertia ixx = "0.01" ixy = "0.01" ixz = "0.01" iyy = "0.01" iyz = "0.01" izz = "0.01" />
    </inertial>

    <collision>
        <origin rpy="0 0 0" xyz="0.0252 0 0.27"/>
            <geometry>
                <box size="0.0254 0.0254 0.54"/>
            </geometry>
    </collision>

    <visual>
        <origin rpy="0 0 0" xyz="0.0252 0 0.27"/>
            <geometry>
                <box size="0.0254 0.0254 0.54"/>
            </geometry>
            <material name="red"/>
    </visual>
</link>

            <!-- Upper to Pointer Joint -->

<joint name="upper_pointer_joint" type="revolute">
    <parent link="arm_upper"/>
        <child link="pointer"/>
        <origin xyz="0 0 0.54" rpy="0 0 0"/>
        <limit lower="-3.14159" upper="3.14159" effort="5.4917" velocity="0.5"/>
    <axis xyz="1 0 0"/>
</joint>

<transmission name = "trans_upper_pointer">
    <type>transmission_interface/SimpleTransmission</type>
    <joint name="upper_pointer_joint">
        <hardwareInterface>hardware_interface/EffortJointInterface</hardwareInterface>
    </joint>
    <actuator name="motor_upper_pointer_joint">
        <hardwareInterface>hardware_interface/EffortJointInterface</hardwareInterface>
        <mechanicalReduction>1</mechanicalReduction>
    </actuator>
</transmission>

            <!-- Pointer Link -->

<link name="pointer">

    <inertial>
        <mass value = "0.1" />
        <origin rpy ="0 0 0" xyz ="0 0 0.063" />
        <inertia ixx = "0.01" ixy = "0.01" ixz = "0.01" iyy = "0.01" iyz = "0.01" izz = "0.01" />
    </inertial>

    <collision>
        <origin rpy="0 0 0" xyz="0 0 0.063"/>
            <geometry>
                <box size="0.02 0.02 0.126"/>
            </geometry>
    </collision>

    <visual>
        <origin rpy="0 0 0" xyz="0 0 0.063"/>
            <geometry>
                <box size="0.02 0.02 0.126"/>
            </geometry>
            <material name="blue"/>
    </visual>
</link>

<gazebo>
    <plugin name="gazebo_ros_control" filename="libgazebo_ros_control.so">
    </plugin>
</gazebo>

</robot>